<?xml version="1.0" ?>
<robot name="pendulum1D">

 <!-- Colors -->
  <material name="Grey">
    <color rgba="0.2 0.2 0.2 1.0"/>
  </material>
  <material name="Orange">
    <color rgba="1.0 0.423529411765 0.0392156862745 1.0"/>
  </material>
  <material name="Blue">
  <color rgba="0.5 0.7 1.0 1.0"/>      
  </material>
  <material name="Red">
    <color rgba="1 0 0 1.0"/>      
  </material>

  <link name="base_link">
    <inertial>
      <origin rpy="0 0 0" xyz="0 0 0"/>
      <mass value="1000"/>
      <inertia ixx="1000" ixy="0" ixz="0" iyy="1000" iyz="0" izz="1000"/>
    </inertial>
    <visual>
      <origin rpy="-1.570796327 0 0" xyz="0 0 0"/>
      <geometry>
        <box size="0.3 0.3 0.1" />
      </geometry>
      <material name="Grey"/>
    </visual>
    <collision>
     <origin rpy="-1.570796327 0 0" xyz="0 0 0"/>
      <geometry>
        <box size="0.3 0.3 0.1" />
      </geometry>
    </collision>
  </link>



  <joint name="joint_1" type="revolute">
    <origin rpy="0 0 0" xyz="0.1 0 0"/>
    <parent link="base_link"/>
    <child link="link_1"/>
    <axis xyz="0 1 0"/>
    <limit effort="0" lower="-3.228859205" upper="3.228859205" velocity="2.146755039"/>
  </joint> 

  <link name="link_1">
      <inertial>
      <origin rpy="0 -1.570796327 0" xyz="1 0 0"/>
      <mass value="1000"/>
      <inertia ixx="1000" ixy="0" ixz="0" iyy="1000" iyz="0" izz="1000"/>
    </inertial>
    <visual>
      <origin rpy="0 -1.570796327 0" xyz="1 0 0"/>
      <geometry>
        <cylinder radius="0.05" length="1"/>
      </geometry>
      <material name="Grey"/>
    </visual>
    <collision>
     <origin rpy="0 -1.570796327 0" xyz="1 0 0"/>
      <geometry>
        <cylinder radius="0.05" length="1"/>
      </geometry>
    </collision>
  </link>
 
</robot>